<?xml version="1.0" ?>
<!-- =================================================================================== -->
<!-- |    This document was autogenerated by xacro from kr16_r1610_2.urdf.xacro        | -->
<!-- |    EDITING THIS FILE BY HAND IS NOT RECOMMENDED                                 | -->
<!-- =================================================================================== -->
<robot name="kr16_r1610_2">
  <!-- ros2 control -->
  <ros2_control name="kuka_kr16_r1610_2" type="system">
    <hardware>
      <plugin>kuka_rsi_driver::KukaEkiRsiHardwareInterface</plugin>
      <param name="controller_ip">0.0.0.0</param>
      <param name="client_ip">0.0.0.0</param>
      <param name="client_port">59152</param>
      <param name="name">kr16_r1610_2</param>
      <param name="verify_robot_model">True</param>
    </hardware>
    <joint name="joint_1">
      <command_interface name="position"/>
      <state_interface name="position">
        <param name="initial_value">0.0</param>
      </state_interface>
    </joint>
    <joint name="joint_2">
      <command_interface name="position"/>
      <state_interface name="position">
        <param name="initial_value">-1.5708</param>
      </state_interface>
    </joint>
    <joint name="joint_3">
      <command_interface name="position"/>
      <state_interface name="position">
        <param name="initial_value">1.5708</param>
      </state_interface>
    </joint>
    <joint name="joint_4">
      <command_interface name="position"/>
      <state_interface name="position">
        <param name="initial_value">0.0</param>
      </state_interface>
    </joint>
    <joint name="joint_5">
      <command_interface name="position"/>
      <state_interface name="position">
        <param name="initial_value">0.0</param>
      </state_interface>
    </joint>
    <joint name="joint_6">
      <command_interface name="position"/>
      <state_interface name="position">
        <param name="initial_value">0.0</param>
      </state_interface>
    </joint>
    <gpio name="gpio"/>
  </ros2_control>
  <!-- world link -->
  <link name="world"/>
  <link name="base"/>
  <link name="base_link">
    <collision>
      <geometry>
        <mesh filename="../meshes/kr16_r1610_2/collision/base_link.stl"/>
      </geometry>
      <origin rpy="0.0 -0.0 0.0" xyz="0.0 0.0 0.0"/>
    </collision>
    <inertial>
      <inertia ixx="0.0" ixy="0.0" ixz="0.0" iyy="0.0" iyz="0.0" izz="0.0"/>
      <mass value="6.5217E1"/>
      <origin rpy="0.0 -0.0 0.0" xyz="0.0 0.0 0.0"/>
    </inertial>
    <visual>
      <geometry>
        <mesh filename="../meshes/kr16_r1610_2/visual/base_link.dae"/>
      </geometry>
      <origin rpy="0.0 -0.0 0.0" xyz="0.0 0.0 0.0"/>
    </visual>
  </link>
  <link name="flange"/>
  <link name="link_1">
    <collision>
      <geometry>
        <mesh filename="../meshes/kr16_r1610_2/collision/link_1.stl"/>
      </geometry>
      <origin rpy="-3.141592653589793 0.0 -0.0" xyz="0.0 -3.8294705409337735e-17 0.3127"/>
    </collision>
    <inertial>
      <inertia ixx="0.0" ixy="0.0" ixz="0.0" iyy="0.0" iyz="0.0" izz="1.49867588"/>
      <mass value="8.4207E1"/>
      <origin rpy="0.0 -0.0 0.0" xyz="0.0504706 0.0052813 -0.1312335"/>
    </inertial>
    <visual>
      <geometry>
        <mesh filename="../meshes/kr16_r1610_2/visual/link_1.dae"/>
      </geometry>
      <origin rpy="-3.141592653589793 0.0 -0.0" xyz="0.0 -3.8294705409337735e-17 0.3127"/>
    </visual>
  </link>
  <link name="link_2">
    <collision>
      <geometry>
        <mesh filename="../meshes/kr16_r1610_2/collision/link_2.stl"/>
      </geometry>
      <origin rpy="1.5707963267948968 -0.0 1.5707963267948966" xyz="-0.52 -0.15999999999999998 7.013552218716891e-17"/>
    </collision>
    <inertial>
      <inertia ixx="5.75908612" ixy="0.0" ixz="0.0" iyy="0.58146603" iyz="0.0" izz="6.02146345"/>
      <mass value="5.5581E1"/>
      <origin rpy="0.0 -1.5707963267948966 -1.5707963267948968" xyz="0.30028478257 0.0 -0.0647077"/>
    </inertial>
    <visual>
      <geometry>
        <mesh filename="../meshes/kr16_r1610_2/visual/link_2.dae"/>
      </geometry>
      <origin rpy="1.5707963267948968 -0.0 1.5707963267948966" xyz="-0.52 -0.15999999999999998 7.013552218716891e-17"/>
    </visual>
  </link>
  <link name="link_3">
    <collision>
      <geometry>
        <mesh filename="../meshes/kr16_r1610_2/collision/link_3.stl"/>
      </geometry>
      <origin rpy="1.5707963267948968 -0.0 -0.0" xyz="-0.16000000000000006 1.3 7.013552218716891e-17"/>
    </collision>
    <inertial>
      <inertia ixx="0.34836069" ixy="0.0" ixz="0.0" iyy="1.0268737" iyz="0.0" izz="1.13887402"/>
      <mass value="3.5648E1"/>
      <origin rpy="0.0 -0.0 0.0" xyz="0.10935396937 0.0 0.045030299999999995"/>
    </inertial>
    <visual>
      <geometry>
        <mesh filename="../meshes/kr16_r1610_2/visual/link_3.dae"/>
      </geometry>
      <origin rpy="1.5707963267948968 -0.0 -0.0" xyz="-0.16000000000000006 1.3 7.013552218716891e-17"/>
    </visual>
  </link>
  <link name="link_4">
    <collision>
      <geometry>
        <mesh filename="../meshes/kr16_r1610_2/collision/link_4.stl"/>
      </geometry>
      <origin rpy="1.8369701987210297e-16 1.5707963267948966 0.0" xyz="-1.45 3.419213863219409e-17 0.587"/>
    </collision>
    <inertial>
      <inertia ixx="0.22866295" ixy="0.0" ixz="0.0" iyy="0.03892192" iyz="0.0" izz="0.24951622"/>
      <mass value="1.46280001E1"/>
      <origin rpy="1.5707963267948966 -0.0 1.5707963267948966" xyz="0.0 0.0 -0.18233026869"/>
    </inertial>
    <visual>
      <geometry>
        <mesh filename="../meshes/kr16_r1610_2/visual/link_4.dae"/>
      </geometry>
      <origin rpy="1.8369701987210297e-16 1.5707963267948966 0.0" xyz="-1.45 3.419213863219409e-17 0.587"/>
    </visual>
  </link>
  <link name="link_5">
    <collision>
      <geometry>
        <mesh filename="../meshes/kr16_r1610_2/collision/link_5.stl"/>
      </geometry>
      <origin rpy="1.5707963267948968 -3.749399456654644e-33 -6.123233995736766e-17" xyz="-0.8150000000000001 1.45 -4.6903972407343906e-18"/>
    </collision>
    <inertial>
      <inertia ixx="0.0" ixy="0.0" ixz="0.0" iyy="0.0" iyz="0.0" izz="0.0"/>
      <mass value="1.0E-6"/>
      <origin rpy="0.0 -0.0 0.0" xyz="0.0 0.0 0.0"/>
    </inertial>
    <visual>
      <geometry>
        <mesh filename="../meshes/kr16_r1610_2/visual/link_5.dae"/>
      </geometry>
      <origin rpy="1.5707963267948968 -3.749399456654644e-33 -6.123233995736766e-17" xyz="-0.8150000000000001 1.45 -4.6903972407343906e-18"/>
    </visual>
  </link>
  <link name="link_6">
    <collision>
      <geometry>
        <mesh filename="../meshes/kr16_r1610_2/collision/link_6.stl"/>
      </geometry>
      <origin rpy="1.2246467991473532e-16 1.5707963267948966 0.0" xyz="-1.4500000000000002 -6.396330231946627e-17 0.968"/>
    </collision>
    <inertial>
      <inertia ixx="0.0" ixy="0.0" ixz="0.0" iyy="0.0" iyz="0.0" izz="0.0"/>
      <mass value="1.0E-6"/>
      <origin rpy="0.0 -0.0 0.0" xyz="0.0 0.0 0.0"/>
    </inertial>
    <visual>
      <geometry>
        <mesh filename="../meshes/kr16_r1610_2/visual/link_6.dae"/>
      </geometry>
      <origin rpy="1.2246467991473532e-16 1.5707963267948966 0.0" xyz="-1.4500000000000002 -6.396330231946627e-17 0.968"/>
    </visual>
  </link>
  <link name="tool0"/>
  <joint name="base_link-base" type="fixed">
    <child link="base"/>
    <parent link="base_link"/>
  </joint>
  <joint name="joint_1" type="revolute">
    <axis xyz="0.0 0.0 1.0"/>
    <child link="link_1"/>
    <limit effort="1.8444E3" lower="-3.2288591125E0" upper="3.2288591125E0" velocity="3.4906585E0"/>
    <origin rpy="3.141592653589793 -0.0 0.0" xyz="0.0 0.0 0.3127"/>
    <parent link="base_link"/>
  </joint>
  <joint name="joint_2" type="revolute">
    <axis xyz="0.0 0.0 1.0"/>
    <child link="link_2"/>
    <limit effort="1.63453711078E3" lower="-3.2288591125E0" upper="1.1344640125E0" velocity="3.05432619E0"/>
    <origin rpy="1.5707963267948966 -0.0 0.0" xyz="0.16 0.0 -0.2073"/>
    <parent link="link_1"/>
  </joint>
  <joint name="joint_3" type="revolute">
    <axis xyz="0.0 0.0 1.0"/>
    <child link="link_3"/>
    <limit effort="8.1441288241E2" lower="-2.408554365E0" upper="3.0543261875E0" velocity="3.31612558E0"/>
    <origin rpy="0.0 -0.0 0.0" xyz="0.78 0.0 0.0"/>
    <parent link="link_2"/>
  </joint>
  <joint name="joint_4" type="revolute">
    <axis xyz="0.0 0.0 1.0"/>
    <child link="link_4"/>
    <limit effort="2.5163043332E2" lower="-6.108652375E0" upper="6.108652375E0" velocity="7.50491578E0"/>
    <origin rpy="1.5707963267948966 -0.0 -1.5707963267948966" xyz="0.427 -0.15 0.0"/>
    <parent link="link_3"/>
  </joint>
  <joint name="joint_5" type="revolute">
    <axis xyz="0.0 0.0 1.0"/>
    <child link="link_5"/>
    <limit effort="2.4142476663E2" lower="-2.268928025E0" upper="2.268928025E0" velocity="7.50491578E0"/>
    <origin rpy="0.0 1.5707963267948966 1.5707963267948966" xyz="0.0 0.0 -0.228"/>
    <parent link="link_4"/>
  </joint>
  <joint name="joint_6" type="revolute">
    <axis xyz="0.0 0.0 1.0"/>
    <child link="link_6"/>
    <limit effort="1.0558296E2" lower="-6.108652375E0" upper="6.108652375E0" velocity="1.099557429E1"/>
    <origin rpy="1.5707963267948966 -0.0 -1.5707963267948966" xyz="0.153 0.0 0.0"/>
    <parent link="link_5"/>
  </joint>
  <joint name="link6-flange" type="fixed">
    <child link="flange"/>
    <origin rpy="0.0 1.5707963267948966 0.0" xyz="0.0 0.0 0.0"/>
    <parent link="link_6"/>
  </joint>
  <joint name="link6-tool0" type="fixed">
    <child link="tool0"/>
    <origin rpy="3.141592653589793 1.2246467991473532E-16 3.141592653589793" xyz="0.0 0.0 0.0"/>
    <parent link="link_6"/>
  </joint>
  <!-- default world - base_link joint -->
  <joint name="world-base_link" type="fixed">
    <parent link="world"/>
    <child link="base_link"/>
    <origin rpy="0 0 0" xyz="0 0 0"/>
  </joint>
</robot>

