<?xml version="1.0" ?>
<!-- =================================================================================== -->
<!-- |    This document was autogenerated by xacro from lbr_iiwa14_r820.urdf.xacro     | -->
<!-- |    EDITING THIS FILE BY HAND IS NOT RECOMMENDED                                 | -->
<!-- =================================================================================== -->
<robot name="lbr_iiwa14_r820">
  <!-- ros2 control -->
  <ros2_control name="kuka_lbr_iiwa14_r820" type="system">
    <hardware>
      <plugin>kuka_sunrise_fri_driver::KukaFRIHardwareInterface</plugin>
      <param name="controller_ip">0.0.0.0</param>
      <param name="client_ip">0.0.0.0</param>
      <param name="client_port">30200</param>
    </hardware>
    <!-- define joints and command/state interfaces for each joint -->
    <joint name="joint_1">
      <command_interface name="position"/>
      <command_interface name="stiffness"/>
      <command_interface name="damping"/>
      <command_interface name="effort"/>
      <state_interface name="position">
        <param name="initial_value">0.0</param>
      </state_interface>
      <state_interface name="effort">
        <param name="initial_value">0.0</param>
      </state_interface>
      <state_interface name="external_torque">
        <param name="initial_value">0.0</param>
      </state_interface>
      <state_interface name="commanded_position">
        <param name="initial_value">0.0</param>
      </state_interface>
    </joint>
    <joint name="joint_2">
      <command_interface name="position"/>
      <command_interface name="stiffness"/>
      <command_interface name="damping"/>
      <command_interface name="effort"/>
      <state_interface name="position">
        <param name="initial_value">0.0</param>
      </state_interface>
      <state_interface name="effort">
        <param name="initial_value">0.0</param>
      </state_interface>
      <state_interface name="external_torque">
        <param name="initial_value">0.0</param>
      </state_interface>
      <state_interface name="commanded_position">
        <param name="initial_value">0.0</param>
      </state_interface>
    </joint>
    <joint name="joint_3">
      <command_interface name="position"/>
      <command_interface name="stiffness"/>
      <command_interface name="damping"/>
      <command_interface name="effort"/>
      <state_interface name="position">
        <param name="initial_value">0.0</param>
      </state_interface>
      <state_interface name="effort">
        <param name="initial_value">0.0</param>
      </state_interface>
      <state_interface name="external_torque">
        <param name="initial_value">0.0</param>
      </state_interface>
      <state_interface name="commanded_position">
        <param name="initial_value">0.0</param>
      </state_interface>
    </joint>
    <joint name="joint_4">
      <command_interface name="position"/>
      <command_interface name="stiffness"/>
      <command_interface name="damping"/>
      <command_interface name="effort"/>
      <state_interface name="position">
        <param name="initial_value">0.0</param>
      </state_interface>
      <state_interface name="effort">
        <param name="initial_value">0.0</param>
      </state_interface>
      <state_interface name="external_torque">
        <param name="initial_value">0.0</param>
      </state_interface>
      <state_interface name="commanded_position">
        <param name="initial_value">0.0</param>
      </state_interface>
    </joint>
    <joint name="joint_5">
      <command_interface name="position"/>
      <command_interface name="stiffness"/>
      <command_interface name="damping"/>
      <command_interface name="effort"/>
      <state_interface name="position">
        <param name="initial_value">0.0</param>
      </state_interface>
      <state_interface name="effort">
        <param name="initial_value">0.0</param>
      </state_interface>
      <state_interface name="external_torque">
        <param name="initial_value">0.0</param>
      </state_interface>
      <state_interface name="commanded_position">
        <param name="initial_value">0.0</param>
      </state_interface>
    </joint>
    <joint name="joint_6">
      <command_interface name="position"/>
      <command_interface name="stiffness"/>
      <command_interface name="damping"/>
      <command_interface name="effort"/>
      <state_interface name="position">
        <param name="initial_value">0.0</param>
      </state_interface>
      <state_interface name="effort">
        <param name="initial_value">0.0</param>
      </state_interface>
      <state_interface name="external_torque">
        <param name="initial_value">0.0</param>
      </state_interface>
      <state_interface name="commanded_position">
        <param name="initial_value">0.0</param>
      </state_interface>
    </joint>
    <joint name="joint_7">
      <command_interface name="position"/>
      <command_interface name="stiffness"/>
      <command_interface name="damping"/>
      <command_interface name="effort"/>
      <state_interface name="position">
        <param name="initial_value">0.0</param>
      </state_interface>
      <state_interface name="effort">
        <param name="initial_value">0.0</param>
      </state_interface>
      <state_interface name="external_torque">
        <param name="initial_value">0.0</param>
      </state_interface>
      <state_interface name="commanded_position">
        <param name="initial_value">0.0</param>
      </state_interface>
    </joint>
    <gpio name="gpio"/>
  </ros2_control>
  <!-- world link -->
  <link name="world"/>
  <!-- links - main serial chain -->
  <link name="base_link">
    <visual>
      <geometry>
        <mesh filename="../meshes/lbr_iiwa14_r820/visual/base_link.stl"/>
      </geometry>
      <origin rpy="-0.0 0.0 0.0" xyz="0.0 0.0 0.0"/>
    </visual>
    <collision>
      <origin rpy="-0.0 0.0 0.0" xyz="0.0 0.0 0.0"/>
      <geometry>
        <mesh filename="../meshes/lbr_iiwa14_r820/collision/base_link.stl"/>
      </geometry>
    </collision>
  </link>
  <link name="link_1">
    <visual>
      <geometry>
        <mesh filename="../meshes/lbr_iiwa14_r820/visual/link_1.stl"/>
      </geometry>
      <origin rpy="-0.0 0.0 0.0" xyz="0.0 0.0 0.0"/>
    </visual>
    <collision>
      <origin rpy="-0.0 0.0 0.0" xyz="0.0 0.0 0.0"/>
      <geometry>
        <mesh filename="../meshes/lbr_iiwa14_r820/collision/link_1.stl"/>
      </geometry>
    </collision>
  </link>
  <link name="link_2">
    <visual>
      <geometry>
        <mesh filename="../meshes/lbr_iiwa14_r820/visual/link_2.stl"/>
      </geometry>
      <origin rpy="-0.0 0.0 0.0" xyz="0.0 0.0 0.0"/>
    </visual>
    <collision>
      <origin rpy="-0.0 0.0 0.0" xyz="0.0 0.0 0.0"/>
      <geometry>
        <mesh filename="../meshes/lbr_iiwa14_r820/collision/link_2.stl"/>
      </geometry>
    </collision>
  </link>
  <link name="link_3">
    <visual>
      <geometry>
        <mesh filename="../meshes/lbr_iiwa14_r820/visual/link_3.stl"/>
      </geometry>
      <origin rpy="-0.0 0.0 0.0" xyz="0.0 0.0 0.0"/>
    </visual>
    <collision>
      <origin rpy="-0.0 0.0 0.0" xyz="0.0 0.0 0.0"/>
      <geometry>
        <mesh filename="../meshes/lbr_iiwa14_r820/collision/link_3.stl"/>
      </geometry>
    </collision>
  </link>
  <link name="link_4">
    <visual>
      <geometry>
        <mesh filename="../meshes/lbr_iiwa14_r820/visual/link_4.stl"/>
      </geometry>
      <origin rpy="-0.0 0.0 0.0" xyz="0.0 0.0 0.0"/>
    </visual>
    <collision>
      <origin rpy="-0.0 0.0 0.0" xyz="0.0 0.0 0.0"/>
      <geometry>
        <mesh filename="../meshes/lbr_iiwa14_r820/collision/link_4.stl"/>
      </geometry>
    </collision>
  </link>
  <link name="link_5">
    <visual>
      <geometry>
        <mesh filename="../meshes/lbr_iiwa14_r820/visual/link_5.stl"/>
      </geometry>
      <origin rpy="-0.0 0.0 0.0" xyz="0.0 0.0 0.0"/>
    </visual>
    <collision>
      <origin rpy="-0.0 0.0 0.0" xyz="0.0 0.0 0.0"/>
      <geometry>
        <mesh filename="../meshes/lbr_iiwa14_r820/collision/link_5.stl"/>
      </geometry>
    </collision>
  </link>
  <link name="link_6">
    <visual>
      <geometry>
        <mesh filename="../meshes/lbr_iiwa14_r820/visual/link_6.stl"/>
      </geometry>
      <origin rpy="-0.0 0.0 0.0" xyz="0.0 0.0 0.0"/>
    </visual>
    <collision>
      <origin rpy="-0.0 0.0 0.0" xyz="0.0 0.0 0.0"/>
      <geometry>
        <mesh filename="../meshes/lbr_iiwa14_r820/collision/link_6.stl"/>
      </geometry>
    </collision>
  </link>
  <link name="link_7">
    <visual>
      <geometry>
        <mesh filename="../meshes/lbr_iiwa14_r820/visual/link_7.stl"/>
      </geometry>
      <origin rpy="-0.0 0.0 0.0" xyz="0.0 0.0 0.0"/>
    </visual>
    <collision>
      <origin rpy="-0.0 0.0 0.0" xyz="0.0 0.0 0.0"/>
      <geometry>
        <mesh filename="../meshes/lbr_iiwa14_r820/collision/link_7.stl"/>
      </geometry>
    </collision>
  </link>
  <!-- joints - main serial chain -->
  <joint name="joint_1" type="revolute">
    <parent link="base_link"/>
    <child link="link_1"/>
    <origin rpy="-0.0 0.0 0.0" xyz="0.0 0.0 0.1575"/>
    <axis xyz="0.0 0.0 1.0"/>
    <limit effort="0" lower="-2.9670597283903604" upper="2.9670597283903604" velocity="1.4835298641951802"/>
  </joint>
  <joint name="joint_2" type="revolute">
    <parent link="link_1"/>
    <child link="link_2"/>
    <origin rpy="-0.0 0.0 0.0" xyz="0.0 0.0 0.2025"/>
    <axis xyz="0.0 1.0 0.0"/>
    <limit effort="0" lower="-2.0943951023931953" upper="2.0943951023931953" velocity="1.4835298641951802"/>
  </joint>
  <joint name="joint_3" type="revolute">
    <parent link="link_2"/>
    <child link="link_3"/>
    <origin rpy="-0.0 0.0 0.0" xyz="0.0 0.0 0.2045"/>
    <axis xyz="0.0 0.0 1.0"/>
    <limit effort="0" lower="-2.9670597283903604" upper="2.9670597283903604" velocity="1.7453292519943295"/>
  </joint>
  <joint name="joint_4" type="revolute">
    <parent link="link_3"/>
    <child link="link_4"/>
    <origin rpy="-0.0 0.0 0.0" xyz="0.0 0.0 0.2155"/>
    <axis xyz="0.0 -1.0 0.0"/>
    <limit effort="0" lower="-2.0943951023931953" upper="2.0943951023931953" velocity="1.3089969389957472"/>
  </joint>
  <joint name="joint_5" type="revolute">
    <parent link="link_4"/>
    <child link="link_5"/>
    <origin rpy="-0.0 0.0 0.0" xyz="0.0 0.0 0.1845"/>
    <axis xyz="0.0 0.0 1.0"/>
    <limit effort="0" lower="-2.9670597283903604" upper="2.9670597283903604" velocity="2.2689280275926285"/>
  </joint>
  <joint name="joint_6" type="revolute">
    <parent link="link_5"/>
    <child link="link_6"/>
    <origin rpy="-0.0 0.0 0.0" xyz="0.0 0.0 0.2155"/>
    <axis xyz="0.0 1.0 0.0"/>
    <limit effort="0" lower="-2.0943951023931953" upper="2.0943951023931953" velocity="2.356194490192345"/>
  </joint>
  <joint name="joint_7" type="revolute">
    <parent link="link_6"/>
    <child link="link_7"/>
    <origin rpy="-0.0 0.0 0.0" xyz="0.0 0.0 0.081"/>
    <axis xyz="0.0 0.0 1.0"/>
    <limit effort="0" lower="-3.0543261909900767" upper="3.0543261909900767" velocity="2.356194490192345"/>
  </joint>
  <!-- ROS-Industrial 'base' frame - equivalent of 'KUKA ROBROOT'-->
  <link name="base"/>
  <joint name="base_link-base" type="fixed">
    <origin rpy="0 0 0" xyz="0 0 0"/>
    <parent link="base_link"/>
    <child link="base"/>
  </joint>
  <!-- ROS-Industrial 'flange' frame - attachment point for EEF models -->
  <link name="flange"/>
  <joint name="link7-flange" type="fixed">
    <parent link="link_7"/>
    <child link="flange"/>
    <origin rpy="-0.0 0.0 0.0" xyz="0.0 0.0 0.071"/>
  </joint>
  <!-- ROS-Industrial 'tool0' frame - all-zeros tool frame -->
  <link name="tool0"/>
  <joint name="link7-tool0" type="fixed">
    <parent link="link_7"/>
    <child link="tool0"/>
    <origin rpy="-0.0 0.0 0.0" xyz="0.0 0.0 0.071"/>
  </joint>
  <!-- default world - base_link joint -->
  <joint name="world-base_link" type="fixed">
    <parent link="world"/>
    <child link="base_link"/>
    <origin rpy="0 0 0" xyz="0 0 0"/>
  </joint>
</robot>

